<?xml version="1.0"?>
<robot name="enhanced_humanoid" xmlns:xacro="http://www.ros.org/wiki/xacro">
  <!-- Base Link -->
  <link name="base_link">
    <visual>
      <geometry>
        <box size="0.3 0.2 0.15"/>
      </geometry>
      <material name="blue">
        <color rgba="0 0 1 0.8"/>
      </material>
    </visual>
    <collision>
      <geometry>
        <box size="0.3 0.2 0.15"/>
      </geometry>
    </collision>
    <inertial>
      <mass value="5.0"/>
      <inertia ixx="0.1" ixy="0.0" ixz="0.0" iyy="0.1" iyz="0.0" izz="0.1"/>
    </inertial>
  </link>

  <!-- Head -->
  <joint name="head_joint" type="fixed">
    <parent link="base_link"/>
    <child link="head"/>
    <origin xyz="0 0 0.25" rpy="0 0 0"/>
  </joint>

  <link name="head">
    <visual>
      <geometry>
        <sphere radius="0.1"/>
      </geometry>
      <material name="white">
        <color rgba="1 1 1 0.8"/>
      </material>
    </visual>
    <collision>
      <geometry>
        <sphere radius="0.1"/>
      </geometry>
    </collision>
    <inertial>
      <mass value="1.0"/>
      <inertia ixx="0.004" ixy="0.0" ixz="0.0" iyy="0.004" iyz="0.0" izz="0.004"/>
    </inertial>
  </link>

  <!-- Left Arm -->
  <joint name="left_arm_joint" type="revolute">
    <parent link="base_link"/>
    <child link="left_arm"/>
    <origin xyz="0.2 0 0" rpy="0 0 0"/>
    <axis xyz="0 1 0"/>
    <limit lower="-1.57" upper="1.57" effort="100" velocity="1"/>
    <safety_controller k_position="100.0" k_velocity="10.0" soft_lower_limit="-1.5" soft_upper_limit="1.5"/>
  </joint>

  <link name="left_arm">
    <visual>
      <geometry>
        <cylinder length="0.3" radius="0.05"/>
      </geometry>
      <material name="red">
        <color rgba="1 0 0 0.8"/>
      </material>
    </visual>
    <collision>
      <geometry>
        <cylinder length="0.3" radius="0.05"/>
      </geometry>
    </collision>
    <inertial>
      <mass value="1.0"/>
      <inertia ixx="0.005" ixy="0.0" ixz="0.0" iyy="0.005" iyz="0.0" izz="0.0005"/>
    </inertial>
  </link>

  <!-- Right Arm -->
  <joint name="right_arm_joint" type="revolute">
    <parent link="base_link"/>
    <child link="right_arm"/>
    <origin xyz="-0.2 0 0" rpy="0 0 0"/>
    <axis xyz="0 1 0"/>
    <limit lower="-1.57" upper="1.57" effort="100" velocity="1"/>
    <safety_controller k_position="100.0" k_velocity="10.0" soft_lower_limit="-1.5" soft_upper_limit="1.5"/>
  </joint>

  <link name="right_arm">
    <visual>
      <geometry>
        <cylinder length="0.3" radius="0.05"/>
      </geometry>
      <material name="red">
        <color rgba="1 0 0 0.8"/>
      </material>
    </visual>
    <collision>
      <geometry>
        <cylinder length="0.3" radius="0.05"/>
      </geometry>
    </collision>
    <inertial>
      <mass value="1.0"/>
      <inertia ixx="0.005" ixy="0.0" ixz="0.0" iyy="0.005" iyz="0.0" izz="0.0005"/>
    </inertial>
  </link>

  <!-- Left Leg -->
  <joint name="left_leg_joint" type="revolute">
    <parent link="base_link"/>
    <child link="left_leg"/>
    <origin xyz="0.1 -0.1 -0.3" rpy="0 0 0"/>
    <axis xyz="0 1 0"/>
    <limit lower="-1.57" upper="1.57" effort="100" velocity="1"/>
    <safety_controller k_position="100.0" k_velocity="10.0" soft_lower_limit="-1.5" soft_upper_limit="1.5"/>
  </joint>

  <link name="left_leg">
    <visual>
      <geometry>
        <cylinder length="0.4" radius="0.05"/>
      </geometry>
      <material name="green">
        <color rgba="0 1 0 0.8"/>
      </material>
    </visual>
    <collision>
      <geometry>
        <cylinder length="0.4" radius="0.05"/>
      </geometry>
    </collision>
    <inertial>
      <mass value="1.0"/>
      <inertia ixx="0.007" ixy="0.0" ixz="0.0" iyy="0.007" iyz="0.0" izz="0.0005"/>
    </inertial>
  </link>

  <!-- Right Leg -->
  <joint name="right_leg_joint" type="revolute">
    <parent link="base_link"/>
    <child link="right_leg"/>
    <origin xyz="0.1 0.1 -0.3" rpy="0 0 0"/>
    <axis xyz="0 1 0"/>
    <limit lower="-1.57" upper="1.57" effort="100" velocity="1"/>
    <safety_controller k_position="100.0" k_velocity="10.0" soft_lower_limit="-1.5" soft_upper_limit="1.5"/>
  </joint>

  <link name="right_leg">
    <visual>
      <geometry>
        <cylinder length="0.4" radius="0.05"/>
      </geometry>
      <material name="green">
        <color rgba="0 1 0 0.8"/>
      </material>
    </visual>
    <collision>
      <geometry>
        <cylinder length="0.4" radius="0.05"/>
      </geometry>
    </collision>
    <inertial>
      <mass value="1.0"/>
      <inertia ixx="0.007" ixy="0.0" ixz="0.0" iyy="0.007" iyz="0.0" izz="0.0005"/>
    </inertial>
  </link>

  <!-- Sensors -->
  <!-- IMU Sensor -->
  <joint name="imu_joint" type="fixed">
    <parent link="base_link"/>
    <child link="imu_link"/>
    <origin xyz="0 0 0" rpy="0 0 0"/>
  </joint>

  <link name="imu_link">
    <inertial>
      <mass value="0.01"/>
      <inertia ixx="0.0001" ixy="0" ixz="0" iyy="0.0001" iyz="0" izz="0.0001"/>
    </inertial>
  </link>

  <gazebo reference="imu_link">
    <sensor name="imu_sensor" type="imu">
      <always_on>true</always_on>
      <update_rate>100</update_rate>
      <imu>
        <angular_velocity>
          <x>
            <noise type="gaussian">
              <mean>0.0</mean>
              <stddev>0.0087</stddev>
            </noise>
          </x>
          <y>
            <noise type="gaussian">
              <mean>0.0</mean>
              <stddev>0.0087</stddev>
            </noise>
          </y>
          <z>
            <noise type="gaussian">
              <mean>0.0</mean>
              <stddev>0.0087</stddev>
            </noise>
          </z>
        </angular_velocity>
        <linear_acceleration>
          <x>
            <noise type="gaussian">
              <mean>0.0</mean>
              <stddev>0.017</stddev>
            </noise>
          </x>
          <y>
            <noise type="gaussian">
              <mean>0.0</mean>
              <stddev>0.017</stddev>
            </noise>
          </y>
          <z>
            <noise type="gaussian">
              <mean>0.0</mean>
              <stddev>0.017</stddev>
            </noise>
          </z>
        </linear_acceleration>
      </imu>
    </sensor>
  </gazebo>

  <!-- LiDAR Sensor -->
  <joint name="lidar_joint" type="fixed">
    <parent link="base_link"/>
    <child link="lidar_link"/>
    <origin xyz="0.15 0 0.05" rpy="0 0 0"/>
  </joint>

  <link name="lidar_link">
    <inertial>
      <mass value="0.1"/>
      <inertia ixx="0.001" ixy="0" ixz="0" iyy="0.001" iyz="0" izz="0.001"/>
    </inertial>
    <visual>
      <geometry>
        <cylinder radius="0.05" length="0.04"/>
      </geometry>
      <material name="black">
        <color rgba="0 0 0 1"/>
      </material>
    </visual>
    <collision>
      <geometry>
        <cylinder radius="0.05" length="0.04"/>
      </geometry>
    </collision>
  </link>

  <gazebo reference="lidar_link">
    <sensor name="lidar_sensor" type="ray">
      <always_on>true</always_on>
      <visualize>false</visualize>
      <update_rate>10</update_rate>
      <ray>
        <scan>
          <horizontal>
            <samples>360</samples>
            <resolution>1.0</resolution>
            <min_angle>-2.3562</min_angle>
            <max_angle>2.3562</max_angle>
          </horizontal>
        </scan>
        <range>
          <min>0.1</min>
          <max>30.0</max>
          <resolution>0.01</resolution>
        </range>
      </ray>
      <plugin name="lidar_controller" filename="libgazebo_ros_ray_sensor.so">
        <ros>
          <namespace>/sensor_data</namespace>
          <remapping>~/out:=lidar</remapping>
        </ros>
        <output_type>sensor_msgs/LaserScan</output_type>
      </plugin>
    </sensor>
  </gazebo>

  <!-- Depth Camera -->
  <joint name="camera_joint" type="fixed">
    <parent link="head"/>
    <child link="camera_link"/>
    <origin xyz="0.05 0 0" rpy="0 0 0"/>
  </joint>

  <link name="camera_link">
    <inertial>
      <mass value="0.1"/>
      <inertia ixx="0.001" ixy="0" ixz="0" iyy="0.001" iyz="0" izz="0.001"/>
    </inertial>
  </link>

  <gazebo reference="camera_link">
    <sensor name="depth_camera" type="depth">
      <always_on>true</always_on>
      <visualize>false</visualize>
      <update_rate>15</update_rate>
      <camera>
        <horizontal_fov>1.0472</horizontal_fov>
        <image>
          <width>640</width>
          <height>480</height>
          <format>R8G8B8</format>
        </image>
        <clip>
          <near>0.1</near>
          <far>10</far>
        </clip>
      </camera>
      <plugin name="camera_controller" filename="libgazebo_ros_openni_kinect.so">
        <ros>
          <namespace>/sensor_data</namespace>
          <remapping>depth/image_raw:=depth_camera</remapping>
        </ros>
        <camera_name>depth_camera</camera_name>
        <frame_name>camera_link</frame_name>
      </plugin>
    </sensor>
  </gazebo>

  <!-- Gazebo plugin for ROS control -->
  <gazebo>
    <plugin name="gazebo_ros_control" filename="libgazebo_ros_control.so">
      <robotNamespace>/enhanced_humanoid</robotNamespace>
    </plugin>
  </gazebo>

  <!-- Transmission for joints -->
  <transmission name="left_arm_trans">
    <type>transmission_interface/SimpleTransmission</type>
    <joint name="left_arm_joint">
      <hardwareInterface>hardware_interface/PositionJointInterface</hardwareInterface>
    </joint>
    <actuator name="left_arm_motor">
      <hardwareInterface>hardware_interface/PositionJointInterface</hardwareInterface>
      <mechanicalReduction>1</mechanicalReduction>
    </actuator>
  </transmission>

  <transmission name="right_arm_trans">
    <type>transmission_interface/SimpleTransmission</type>
    <joint name="right_arm_joint">
      <hardwareInterface>hardware_interface/PositionJointInterface</hardwareInterface>
    </joint>
    <actuator name="right_arm_motor">
      <hardwareInterface>hardware_interface/PositionJointInterface</hardwareInterface>
      <mechanicalReduction>1</mechanicalReduction>
    </actuator>
  </transmission>

  <transmission name="left_leg_trans">
    <type>transmission_interface/SimpleTransmission</type>
    <joint name="left_leg_joint">
      <hardwareInterface>hardware_interface/PositionJointInterface</hardwareInterface>
    </joint>
    <actuator name="left_leg_motor">
      <hardwareInterface>hardware_interface/PositionJointInterface</hardwareInterface>
      <mechanicalReduction>1</mechanicalReduction>
    </actuator>
  </transmission>

  <transmission name="right_leg_trans">
    <type>transmission_interface/SimpleTransmission</type>
    <joint name="right_leg_joint">
      <hardwareInterface>hardware_interface/PositionJointInterface</hardwareInterface>
    </joint>
    <actuator name="right_leg_motor">
      <hardwareInterface>hardware_interface/PositionJointInterface</hardwareInterface>
      <mechanicalReduction>1</mechanicalReduction>
    </actuator>
  </transmission>
</robot>