<?xml version="1.0"?>
<robot name="simple_humanoid" xmlns:xacro="http://www.ros.org/wiki/xacro">
  <!-- Base Link -->
  <link name="base_link">
    <visual>
      <geometry>
        <box size="0.3 0.2 0.15"/>
      </geometry>
      <material name="blue">
        <color rgba="0 0 1 0.8"/>
      </material>
    </visual>
    <collision>
      <geometry>
        <box size="0.3 0.2 0.15"/>
      </geometry>
    </collision>
    <inertial>
      <mass value="5.0"/>
      <inertia ixx="0.1" ixy="0.0" ixz="0.0" iyy="0.1" iyz="0.0" izz="0.1"/>
    </inertial>
  </link>

  <!-- Head -->
  <joint name="head_joint" type="fixed">
    <parent link="base_link"/>
    <child link="head"/>
    <origin xyz="0 0 0.25" rpy="0 0 0"/>
  </joint>

  <link name="head">
    <visual>
      <geometry>
        <sphere radius="0.1"/>
      </geometry>
      <material name="white">
        <color rgba="1 1 1 0.8"/>
      </material>
    </visual>
    <collision>
      <geometry>
        <sphere radius="0.1"/>
      </geometry>
    </collision>
    <inertial>
      <mass value="1.0"/>
      <inertia ixx="0.004" ixy="0.0" ixz="0.0" iyy="0.004" iyz="0.0" izz="0.004"/>
    </inertial>
  </link>

  <!-- Left Arm -->
  <joint name="left_arm_joint" type="revolute">
    <parent link="base_link"/>
    <child link="left_arm"/>
    <origin xyz="0.2 0 0" rpy="0 0 0"/>
    <axis xyz="0 1 0"/>
    <limit lower="-1.57" upper="1.57" effort="100" velocity="1"/>
    <safety_controller k_position="100.0" k_velocity="10.0" soft_lower_limit="-1.5" soft_upper_limit="1.5"/>
  </joint>

  <link name="left_arm">
    <visual>
      <geometry>
        <cylinder length="0.3" radius="0.05"/>
      </geometry>
      <material name="red">
        <color rgba="1 0 0 0.8"/>
      </material>
    </visual>
    <collision>
      <geometry>
        <cylinder length="0.3" radius="0.05"/>
      </geometry>
    </collision>
    <inertial>
      <mass value="1.0"/>
      <inertia ixx="0.005" ixy="0.0" ixz="0.0" iyy="0.005" iyz="0.0" izz="0.0005"/>
    </inertial>
  </link>

  <!-- Right Arm -->
  <joint name="right_arm_joint" type="revolute">
    <parent link="base_link"/>
    <child link="right_arm"/>
    <origin xyz="-0.2 0 0" rpy="0 0 0"/>
    <axis xyz="0 1 0"/>
    <limit lower="-1.57" upper="1.57" effort="100" velocity="1"/>
    <safety_controller k_position="100.0" k_velocity="10.0" soft_lower_limit="-1.5" soft_upper_limit="1.5"/>
  </joint>

  <link name="right_arm">
    <visual>
      <geometry>
        <cylinder length="0.3" radius="0.05"/>
      </geometry>
      <material name="red">
        <color rgba="1 0 0 0.8"/>
      </material>
    </visual>
    <collision>
      <geometry>
        <cylinder length="0.3" radius="0.05"/>
      </geometry>
    </collision>
    <inertial>
      <mass value="1.0"/>
      <inertia ixx="0.005" ixy="0.0" ixz="0.0" iyy="0.005" iyz="0.0" izz="0.0005"/>
    </inertial>
  </link>

  <!-- Left Leg -->
  <joint name="left_leg_joint" type="revolute">
    <parent link="base_link"/>
    <child link="left_leg"/>
    <origin xyz="0.1 -0.1 -0.3" rpy="0 0 0"/>
    <axis xyz="0 1 0"/>
    <limit lower="-1.57" upper="1.57" effort="100" velocity="1"/>
    <safety_controller k_position="100.0" k_velocity="10.0" soft_lower_limit="-1.5" soft_upper_limit="1.5"/>
  </joint>

  <link name="left_leg">
    <visual>
      <geometry>
        <cylinder length="0.4" radius="0.05"/>
      </geometry>
      <material name="green">
        <color rgba="0 1 0 0.8"/>
      </material>
    </visual>
    <collision>
      <geometry>
        <cylinder length="0.4" radius="0.05"/>
      </geometry>
    </collision>
    <inertial>
      <mass value="1.0"/>
      <inertia ixx="0.007" ixy="0.0" ixz="0.0" iyy="0.007" iyz="0.0" izz="0.0005"/>
    </inertial>
  </link>

  <!-- Right Leg -->
  <joint name="right_leg_joint" type="revolute">
    <parent link="base_link"/>
    <child link="right_leg"/>
    <origin xyz="0.1 0.1 -0.3" rpy="0 0 0"/>
    <axis xyz="0 1 0"/>
    <limit lower="-1.57" upper="1.57" effort="100" velocity="1"/>
    <safety_controller k_position="100.0" k_velocity="10.0" soft_lower_limit="-1.5" soft_upper_limit="1.5"/>
  </joint>

  <link name="right_leg">
    <visual>
      <geometry>
        <cylinder length="0.4" radius="0.05"/>
      </geometry>
      <material name="green">
        <color rgba="0 1 0 0.8"/>
      </material>
    </visual>
    <collision>
      <geometry>
        <cylinder length="0.4" radius="0.05"/>
      </geometry>
    </collision>
    <inertial>
      <mass value="1.0"/>
      <inertia ixx="0.007" ixy="0.0" ixz="0.0" iyy="0.007" iyz="0.0" izz="0.0005"/>
    </inertial>
  </link>

  <!-- Gazebo plugin for ROS control -->
  <gazebo>
    <plugin name="gazebo_ros_control" filename="libgazebo_ros_control.so">
      <robotNamespace>/simple_humanoid</robotNamespace>
    </plugin>
  </gazebo>

  <!-- Transmission for joints -->
  <transmission name="left_arm_trans">
    <type>transmission_interface/SimpleTransmission</type>
    <joint name="left_arm_joint">
      <hardwareInterface>hardware_interface/PositionJointInterface</hardwareInterface>
    </joint>
    <actuator name="left_arm_motor">
      <hardwareInterface>hardware_interface/PositionJointInterface</hardwareInterface>
      <mechanicalReduction>1</mechanicalReduction>
    </actuator>
  </transmission>

  <transmission name="right_arm_trans">
    <type>transmission_interface/SimpleTransmission</type>
    <joint name="right_arm_joint">
      <hardwareInterface>hardware_interface/PositionJointInterface</hardwareInterface>
    </joint>
    <actuator name="right_arm_motor">
      <hardwareInterface>hardware_interface/PositionJointInterface</hardwareInterface>
      <mechanicalReduction>1</mechanicalReduction>
    </actuator>
  </transmission>

  <transmission name="left_leg_trans">
    <type>transmission_interface/SimpleTransmission</type>
    <joint name="left_leg_joint">
      <hardwareInterface>hardware_interface/PositionJointInterface</hardwareInterface>
    </joint>
    <actuator name="left_leg_motor">
      <hardwareInterface>hardware_interface/PositionJointInterface</hardwareInterface>
      <mechanicalReduction>1</mechanicalReduction>
    </actuator>
  </transmission>

  <transmission name="right_leg_trans">
    <type>transmission_interface/SimpleTransmission</type>
    <joint name="right_leg_joint">
      <hardwareInterface>hardware_interface/PositionJointInterface</hardwareInterface>
    </joint>
    <actuator name="right_leg_motor">
      <hardwareInterface>hardware_interface/PositionJointInterface</hardwareInterface>
      <mechanicalReduction>1</mechanicalReduction>
    </actuator>
  </transmission>
</robot>